Workbook

Sheet General Ledger
A1: Foot's Print and Design Shop Inc.
A2: General Ledger
A4: [1] | B4: Cash | D4: 17836
B5: Accounts Receivable | D5: 30910
B6: Sales | E6: =D5+D4 -> 48746
A8: [2] | B8: Sales Discounts | D8: 835
B9: Accounts Receivable | E9: =D8 -> 835
A11: 37715
A12: [3] | B12: Sales Returns & Allowances | D12: 25
B13: Accounts Receivable | E13: 25
A15: 37765
A16: [4] | B16: Allowance for Doubtful Accounts | D16: 304
B17: Accounts Receivable | E17: =D16 -> 304
A19: 37784
A20: [5] | B20: Accounts Receivable | D20: =870*0.3 -> 261
B21: Allowance for Doubtful Accounts | E21: =D20 -> 261
B22: 870*30%=261
A24: [6] | B24: Cash | D24: 261
B25: Accounts Receivable | E25: 261
A27: 37833
A28: [7] | B28: Notes Receivable | D28: 667
B29: Accounts Receivable | E29: =D28 -> 667
B30: ***9% per annum
A32: 37837
A33: [8] | B33: Allowance for Doubtful Accounts | D33: 2036
B34: Accounts Receivable | E34: =D33 -> 2036
A36: 37889
A37: [9] | B37: Sales Returns & Allowances | D37: 215
B38: Unearned Revenue | E38: 215
A40: September 30, 2003
A41: [10] | B41: Cash | D41: ='T-Accounts'!K13 -> 29393
B42: Accounts Receivable | E42: ='T-Accounts'!K13 -> 29393
B43: 56,728 (T/B) - 27,335 (E/B) = 29,393 (plug)
A45: [11] | B45: Interest Receivable | D45: =667*9%*2/12 -> 10.005
B46: Interest Revenue | E46: =D45 -> 10.005
B47: 667*9%*(2/12)=10
A50: [12] | B50: Bad Debts Expense | D50: =F59-321 -> 1109.85
B51: Allowance for Doubtful Accounts | E51: =D50 -> 1109.85
B53: Aging Schedule | D53: Amount | E53: % | F53: $ Uncollectable
B54: Not Yet Due | D54: 16230 | E54: 0.02 | F54: =D54*E54 -> 324.6
...

Sheet T-Accounts
A1: ASSETS | M1: LIABILITIES & OWNER'S EQUITY
A2: Cash | D2: Notes Rec. | G2: AFDA | J2: A/R | N2: Unearned Revenue
A3: 1033 | B3: O/B | D3: ='General Ledger'!D28 -> 667 | E3: ='General Ledger'!A28 -> [7] | G3: O/B | H3: 2400 | J3: 29685 | K3: O/B | N3: ='General Ledger'!A37 -> [9] | O3: ='General Ledger'!E38 -> 215
A4: ='General Ledger'!D4 -> 17836 | B4: ='General Ledger'!A4 -> [1] | D4: =D3 -> 667 | E4: E/B | G4: ='General Ledger'!D16 -> 304 | H4: ='General Ledger'!A16 -> [4] | J4: ='General Ledger'!D5 -> 30910 | K4: ='General Ledger'!A4 -> [1] | N4: E/B | O4: =O3 -> 215
A5: ='General Ledger'!D24 -> 261 | B5: ='General Ledger'!A24 -> [6] | G5: ='General Ledger'!A20 -> [5] | H5: ='General Ledger'!E21 -> 261 | J5: ='General Ledger'!A8 -> [2] | K5: ='General Ledger'!E9 -> 835
A6: =K13 -> 29393 | B6: plug [10] | G6: ='General Ledger'!D33 -> 2036 | H6: ='General Ledger'!A33 -> [8] | J6: ='General Ledger'!A12 -> [3] | K6: ='General Ledger'!E13 -> 25
A7: =SUM(A3:A6) -> 48523 | B7: E/B | G7: T/B | H7: =H3-G4+H5-G6 -> 321 | J7: ='General Ledger'!A16 -> [4] | K7: ='General Ledger'!E17 -> 304
G8: [12] | H8: =H9-H7 -> 1109.85 | J8: ='General Ledger'!D20 -> 261 | K8: ='General Ledger'!A20 -> [5]
G9: E/B | H9: ='General Ledger'!F59 -> 1430.85 | J9: ='General Ledger'!A24 -> [6] | K9: ='General Ledger'!E25 -> 261
J10: ='General Ledger'!A28 -> [7] | K10: ='General Ledger'!E29 -> 667
G11: =J14-H9 -> 25904.15 | H11: NRV | J11: ='General Ledger'!A33 -> [8] | K11: ='General Ledger'!E34 -> 2036
J12: =J3+J4-SUM(K5:K7)+J8-SUM(K9:K11) -> 56728 | K12: T/B
J13: Plug | K13: =J12-J14 -> 29393
G14: Interest Receivable | J14: 27335 | K14: E/B
G15: ='General Ledger'!D45 -> 10.005 | H15: ='General Ledger'!A45 -> [11]
G16: =G15 -> 10.005 | H16: E/B
A21: EXPENSES | M21: REVENUES
D22: Bad Debts Expense | N22: Sales | Q22: Sales Discounts | T22: Sales R&A
D23: =H8 -> 1109.85 | E23: ='General Ledger'!A50 -> [12] | N23: ='General Ledger'!A4 -> [1] | O23: ='General Ledger'!E6 -> 48746 | Q23: ='General Ledger'!D8 -> 835 | R23: ='General Ledger'!A8 -> [2] | T23: ='General Ledger'!D12 -> 25 | U23: ='General Ledger'!A12 -> [3] | X23: =O24+O30-Q24-T25 -> 47681.005
D24: =D23 -> 1109.85 | E24: E/B | N24: E/B | O24: =O23 -> 48746 | Q24: =Q23 -> 835 | R24: E/B | T24: ='General Ledger'!D37 -> 215 | U24: ='General Ledger'!A37 -> [9] | W24: =D24 -> 1109.85
T25: =T23+T24 -> 240 | U25: E/B | X25: =X23-W24 -> 46571.155
W26: =X25*0.25 -> 11642.789
X27: =X25-W26 -> 34928.366
N28: Interest Revenue
N29: =H15 -> [11] | O29: =G15 -> 10.005
N30: E/B | O30: =O29 -> 10.005
