Workbook

Sheet General Ledger
A1: Forest City Tennis Club - Pro Shop and Bar Lounge
A2: General Ledger
A4: [1] | B4: Cash | D4: 100000
B5: Common Shares | E5: =D4 -> 100000
A7: [2] | B7: Inventory | D7: 16340
B8: Cash | E8: =D7 -> 16340
A10: [3] | B10: Liquor Inventory | D10: 13660
B11: Cash | E11: =D10 -> 13660
A13: [4] | B13: Fixtures | D13: 11000
B14: Cash | E14: =D13 -> 11000
A16: [5] | B16: Glassware | D16: 4000
B17: Cash | E17: =D16 -> 4000
A19: [6] | B19: Cash | D19: 53700
B20: Pro Shop Sales | E20: =D19 -> 53700
A22: [7] | B22: Cash | D22: 22650
B23: Match Revenues | E23: =D22 -> 22650
A25: [8] | B25: Cash | D25: 45600
B26: Instruction Revenues | E26: =D25 -> 45600
A28: [9] | B28: Cash | D28: 64550
B29: Liquor Sales | E29: =D28 -> 64550
A31: [10] | B31: Cash | D31: 3050
B32: Other Revenue | E32: =D31 -> 3050
A34: [11] | B34: Rent Expense | D34: 18000
B35: Prepaid Rent | D35: 1500
B36: Cash | E36: 19500
B37: Rent Expense:1,500*12=18,000
B38: Prepaid Rent: 19,500-18,000=1,500
A40: [12] | B40: Fixtures | D40: 8400
B41: Cash | E41: =D40 -> 8400
A43: [13] | B43: Inventory | D43: 26650
B44: Cash | E44: =D43 -> 26650
A46: [14] | B46: Liquor Inventory | D46: 14400
B47: Cash | E47: =D46 -> 14400
A49: [15] | B49: Wages Expense | D49: 51500
B50: Cash | E50: =D49 -> 51500
B51: 24,000+27,500=51,500
A53: [16] | B53: Salaries Expense | D53: 52000
B54: Cash | E54: =D53 -> 52000
A56: [17] | B56: Fixtures | D56: 4200
B57: Accounts Payable | E57: =D56 -> 4200
...

Sheet T-Accounts
A1: ASSETS | M1: LIABILITIES & OWNER'S EQUITY
A2: CASH | D2: PREPAID RENT | G2: LIQUOR INV | J2: INVENTORY | N2: A/P | Q2: UNEARNED REVENUE | T2: TAXES PAYABLE
A3: ='General Ledger'!D4 -> 100000 | B3: ='General Ledger'!A4 -> [1] | D3: ='General Ledger'!D35 -> 1500 | E3: =B23 -> [11] | G3: ='General Ledger'!D10 -> 13660 | H3: ='General Ledger'!A10 -> [3] | J3: ='General Ledger'!D7 -> 16340 | K3: ='General Ledger'!A7 -> [2] | N3: =E12 -> [17] | O3: =D12 -> 4200 | Q3: =U24 -> [19] | R3: =T24 -> 650 | T3: C3 | U3: =G29 -> 10625.625
A4: =K3 -> [2] | B4: =J3 -> 16340 | D4: =D3 -> 1500 | E4: E/B | G4: ='General Ledger'!D46 -> 14400 | H4: ='General Ledger'!A46 -> [14] | J4: ='General Ledger'!D43 -> 26650 | K4: ='General Ledger'!A43 -> [13] | N4: =K5 -> [18] | O4: =J5 -> 2000 | Q4: E/B | R4: =R3 -> 650 | T4: E/B | U4: =U3 -> 10625.625
A5: =H3 -> [3] | B5: =G3 -> 13660 | G5: =SUM(G3:G4) -> 28060 | H5: T/B | J5: ='General Ledger'!D59 -> 2000 | K5: ='General Ledger'!A59 -> [18] | N5: E/B | O5: =SUM(O3:O4) -> 6200
A6: =E10 -> [4] | B6: =D10 -> 11000 | G6: COGS [26] | H6: =G5-G7 -> 16140 | J6: =SUM(J3:J5) -> 44990 | K6: T/B
A7: =H16 -> [5] | B7: =G16 -> 4000 | G7: 11920 | H7: E/B | J7: COGS [25] | K7: =J6-J8 -> 27110
A8: ='General Ledger'!D19 -> 53700 | B8: ='General Ledger'!A19 -> [6] | J8: 17880 | K8: E/B
A9: ='General Ledger'!D22 -> 22650 | B9: ='General Ledger'!A22 -> [7] | D9: FIXTURES | G9: A/A-FIXTURES
A10: ='General Ledger'!D25 -> 45600 | B10: ='General Ledger'!A25 -> [8] | D10: ='General Ledger'!D13 -> 11000 | E10: ='General Ledger'!A13 -> [4] | G10: =K23 -> [20] | H10: =J23 -> 2200
A11: ='General Ledger'!D28 -> 64550 | B11: ='General Ledger'!A28 -> [9] | D11: ='General Ledger'!D40 -> 8400 | E11: ='General Ledger'!A40 -> [12] | G11: =K24 -> [21] | H11: =J24 -> 131.25
A12: ='General Ledger'!D31 -> 3050 | B12: ='General Ledger'!A31 -> [10] | D12: ='General Ledger'!D56 -> 4200 | E12: ='General Ledger'!A56 -> [17] | G12: E/B | H12: =SUM(H10:H11) -> 2331.25
A13: =B23 -> [11] | B13: ='General Ledger'!E36 -> 19500 | D13: =SUM(D10:D12) -> 23600 | E13: E/B
A14: =E11 -> [12] | B14: =D11 -> 8400 | N14: COMMON SHARES | Q14: RETAINED EARNINGS
A15: =K4 -> [13] | B15: =J4 -> 26650 | D15: A/R | G15: GLASSWARE | J15: A/A-GLASSWARE | N15: ='General Ledger'!A4 -> [1] | O15: ='General Ledger'!E5 -> 100000 | Q15: C5 | R15: =W28 -> 24793.125
A16: =H4 -> [14] | B16: =G4 -> 14400 | D16: ='General Ledger'!D77 -> 15000 | E16: ='General Ledger'!A77 -> [23] | G16: ='General Ledger'!D16 -> 4000 | H16: ='General Ledger'!A16 -> [5] | J16: =K25 -> [22] | K16: =J25 -> 2000 | N16: E/B | O16: =O15 -> 100000 | Q16: E/B | R16: =R15 -> 24793.125
A17: =E23 -> [15] | B17: =D23 -> 51500 | D17: ='General Ledger'!D81 -> 600 | E17: ='General Ledger'!A81 -> [24] | G17: =G16 -> 4000 | H17: E/B | J17: E/B | K17: =K16 -> 2000
A18: =H23 -> [16] | B18: =G23 -> 52000 | D18: =D16+D17 -> 15600 | E18: E/B
A20: =SUM(A3:A19)-SUM(B3:B20) -> 72100 | B20: E/B
A21: EXPENSES | M21: REVENUES
A22: RENT | D22: WAGES | G22: SALARIES | J22: AMORTIZATION | N22: PRO SHOP | Q22: INSTRUCTION | T22: LIQUOR | W22: INCOME SUMMARY
A23: ='General Ledger'!D34 -> 18000 | B23: ='General Ledger'!A34 -> [11] | D23: ='General Ledger'!D49 -> 51500 | E23: ='General Ledger'!A49 -> [15] | G23: ='General Ledger'!D53 -> 52000 | H23: ='General Ledger'!A53 -> [16] | J23: ='General Ledger'!D65 -> 2200 | K23: ='General Ledger'!A65 -> [20] | N23: =B8 -> [6] | O23: =A8 -> 53700 | Q23: =B10 -> [8] | R23: =A10 -> 45600 | T23: =B11 -> [9] | U23: =A11 -> 64550 | W23: C1 | X23: =O23+R25+U25+O31+R29 -> 204500
A24: C2 | B24: =A23 -> 18000 | D24: C2 | E24: =D23 -> 51500 | G24: C2 | H24: =G23 -> 52000 | J24: ='General Ledger'!D69 -> 131.25 | K24: ='General Ledger'!A69 -> [21] | N24: =O23 -> 53700 | O24: C1 | Q24: =E16 -> [23] | R24: =D16 -> 15000 | T24: ='General Ledger'!D62 -> 650 | U24: ='General Ledger'!A62 -> [19] | W24: =A23+D23+G23+J26+D29+A29 -> 169081.25 | X24: C2
J25: ='General Ledger'!D73 -> 2000 | K25: ='General Ledger'!A73 -> [22] | Q25: T/B | R25: =SUM(R23:R24) -> 60600 | T25: T/B | U25: =U23-T24 -> 63900 | W25: T/B | X25: =X23-W24 -> 35418.75
J26: =SUM(J23:J25) -> 4331.25 | K26: T/B | Q26: =R25 -> 60600 | R26: C1 | T26: =U25 -> 63900 | U26: C1 | W26: =X25*0.3 -> 10625.625 | X26: C4
J27: C2 | K27: =J26 -> 4331.25 | W27: T/B | X27: =X25-W26 -> 24793.125
A28: COGS | D28: LIQUOR COGS | G28: TAXES | N28: MATCH | Q28: OTHER | W28: =X27 -> 24793.125 | X28: C5
A29: =K7 -> 27110 | B29: ='General Ledger'!A85 -> [25] | D29: =H6 -> 16140 | E29: ='General Ledger'!A89 -> [26] | G29: =X25*0.3 -> 10625.625 | H29: C3 | N29: =B9 -> [7] | O29: =A9 -> 22650 | Q29: =B12 -> [10] | R29: =A12 -> 3050
A30: C2 | B30: =A29 -> 27110 | D30: C2 | E30: =D29 -> 16140 | G30: C4 | H30: =G29 -> 10625.625 | N30: =E17 -> [24] | O30: =D17 -> 600 | Q30: =R29 -> 3050 | R30: C1
N31: T/B | O31: =O29+O30 -> 23250
N32: =O31 -> 23250 | O32: C1

Sheet Adjusting & Closing Entries
A1: CLOSING ENTRIES
A3: C1 | B3: Pro Shop Revenue | D3: ='T-Accounts'!N24 -> 53700
B4: Instruction Revenue | D4: ='T-Accounts'!Q26 -> 60600
B5: Liquor Revenue | D5: ='T-Accounts'!T26 -> 63900
B6: Match Revenue | D6: ='T-Accounts'!N32 -> 23250
B7: Other Revenue | D7: ='T-Accounts'!Q30 -> 3050
B8: Income Summary | E8: =SUM(D3:D7) -> 204500
A10: C2 | B10: Income Summary | D10: =SUM(E11:E16) -> 169081.25
B11: Amortization | E11: ='T-Accounts'!K27 -> 4331.25
B12: COGS | E12: ='T-Accounts'!B30 -> 27110
B13: Liquor COGS | E13: ='T-Accounts'!E30 -> 16140
B14: Rent | E14: ='T-Accounts'!B24 -> 18000
B15: Salaries | E15: ='T-Accounts'!H24 -> 52000
B16: Wages | E16: ='T-Accounts'!E24 -> 51500
A18: C3 | B18: Taxes Expense | D18: =(E8-D10)*0.3 -> 10625.625
B19: Taxes Payable | E19: =D18 -> 10625.625
A21: C4 | B21: Income Summary | D21: =D18 -> 10625.625
B22: Taxes Expense | E22: =D21 -> 10625.625
A24: C5 | B24: Income Summary | D24: =E8-D10-D18 -> 24793.125
B25: Retained Earnings | E25: =D24 -> 24793.125

Sheet Trial Balance
A1: ='General Ledger'!A1:E1 -> Forest City Tennis Club - Pro Shop and Bar Lounge
A2: Trial Balance
A3: ='Balance Sheet'!A3:D3 -> As At June 30, 2008
A5: Cash | C5: ='T-Accounts'!A20 -> 72100
A6: Accounts Receivable | C6: ='T-Accounts'!D18 -> 15600
A7: Prepaid Rent | C7: ='T-Accounts'!D4 -> 1500
A8: Liquor Inventory | C8: ='T-Accounts'!G7 -> 11920
A9: Inventory | C9: ='T-Accounts'!J8 -> 17880
A10: Fixtures | C10: ='T-Accounts'!D13 -> 23600
A11: A/A-Fixtures | D11: ='T-Accounts'!H12 -> 2331.25
A12: Glassware | C12: ='T-Accounts'!G17 -> 4000
A13: A/A-Glassware | D13: ='T-Accounts'!K17 -> 2000
A14: Accounts Payable | D14: ='T-Accounts'!O5 -> 6200
A15: Unearned Revenue | D15: ='T-Accounts'!R4 -> 650
A16: Taxes Payable | D16: ='T-Accounts'!U4 -> 10625.625
A17: Common Shares | D17: ='T-Accounts'!O16 -> 100000
A18: Retained Earnings | D18: ='T-Accounts'!R16 -> 24793.125
A19: Total: | C19: =SUM(C5:C18) -> 146600 | D19: =SUM(D5:D18) -> 146600

Sheet Income Statement
A1: ='General Ledger'!A1:E1 -> Forest City Tennis Club - Pro Shop and Bar Lounge
A2: Income Statement
A3: For the Year Ended June 30, 2008
A5: Revenues
A6: ='Adjusting & Closing Entries'!B3 -> Pro Shop Revenue | C6: ='Adjusting & Closing Entries'!D3 -> 53700
A7: ='Adjusting & Closing Entries'!B4 -> Instruction Revenue | C7: ='Adjusting & Closing Entries'!D4 -> 60600
A8: ='Adjusting & Closing Entries'!B5 -> Liquor Revenue | C8: ='Adjusting & Closing Entries'!D5 -> 63900
A9: ='Adjusting & Closing Entries'!B6 -> Match Revenue | C9: ='Adjusting & Closing Entries'!D6 -> 23250
A10: ='Adjusting & Closing Entries'!B7 -> Other Revenue | C10: ='Adjusting & Closing Entries'!D7 -> 3050
A11: Total Revenue | D11: =SUM(C6:C10) -> 204500
A13: ='Adjusting & Closing Entries'!B12 -> COGS | C13: ='Adjusting & Closing Entries'!E12 -> 27110
A14: ='Adjusting & Closing Entries'!B13 -> Liquor COGS | C14: ='Adjusting & Closing Entries'!E13 -> 16140 | D14: =C13+C14 -> 43250
A15: Gross Margin | D15: =D11-D14 -> 161250
A17: Operating Expenses
A18: ='Adjusting & Closing Entries'!B11 -> Amortization | C18: ='Adjusting & Closing Entries'!E11 -> 4331.25
A19: ='Adjusting & Closing Entries'!B14 -> Rent | C19: ='Adjusting & Closing Entries'!E14 -> 18000
A20: ='Adjusting & Closing Entries'!B15 -> Salaries | C20: ='Adjusting & Closing Entries'!E15 -> 52000
A21: ='Adjusting & Closing Entries'!B16 -> Wages | C21: ='Adjusting & Closing Entries'!E16 -> 51500
A22: Total Operating Expenses | D22: =SUM(C18:C21) -> 125831.25
A24: Net Income Before Tax | D24: =D15-D22 -> 35418.75
A25: Income Tax Expense | D25: =D24*0.3 -> 10625.625
A26: Net Income | D26: =D24-D25 -> 24793.125

Sheet Balance Sheet
A1: ='Income Statement'!A1:D1 -> Forest City Tennis Club - Pro Shop and Bar Lounge
A2: Balance Sheet
A3: As At June 30, 2008
A5: Assets
A7: Current Assets
A8: Cash | C8: ='T-Accounts'!A20 -> 72100
A9: Accounts Receivable | C9: ='T-Accounts'!D18 -> 15600
A10: Prepaid Rent | C10: ='T-Accounts'!D4 -> 1500
A11: Pro Shop Inventory | C11: ='T-Accounts'!J8 -> 17880
A12: Liquor Inventory | C12: ='T-Accounts'!G7 -> 11920
A13: Total Current Assets | D13: =SUM(C8:C12) -> 119000
A15: Fixed Assets
A16: Fixtures | C16: ='T-Accounts'!D13 -> 23600
A17: A/A-Fixtures | C17: ='T-Accounts'!H12 -> 2331.25 | D17: =C16-C17 -> 21268.75
A18: Glassware | C18: ='T-Accounts'!G17 -> 4000
A19: A/A-Glassware | C19: ='T-Accounts'!K17 -> 2000 | D19: =C18-C19 -> 2000
A20: Total Fixed Assets | D20: =SUM(D16:D19) -> 23268.75
A22: Total Assets | D22: =D13+D20 -> 142268.75
A24: Liabilities & Shareholder's Equity
A26: Current Liabilities
A27: Accounts Payable | C27: ='T-Accounts'!O5 -> 6200
A28: Unearned Revenue | C28: ='T-Accounts'!R4 -> 650
A29: Taxes Payable | C29: ='T-Accounts'!U4 -> 10625.625
A30: Total Current Liabilities | D30: =SUM(C27:C29) -> 17475.625
A32: Shareholder's Equity
A33: Common Shares | C33: ='T-Accounts'!O16 -> 100000
A34: Retained Earnings | C34: ='T-Accounts'!R16 -> 24793.125
A35: Total Shareholder's Equity | D35: =SUM(C33:C34) -> 124793.12
A37: Total Liabilities & Shareholder's Equity | D37: =D30+D35 -> 142268.75
